I'm sorry, but an uncaught exception occurred.

While running game code:
  File "game/script.rpy", line 287, in script
    a "Hmmm... có gì thì phải nói với tớ đấy nhé"
KeyError: 'playername'

-- Full Traceback ------------------------------------------------------------

Full traceback:
  File "game/script.rpy", line 287, in script
    a "Hmmm... có gì thì phải nói với tớ đấy nhé"
  File "C:\Users\ASUS\Downloads\renpy-8.0.3-sdk\renpy\ast.py", line 921, in execute
    renpy.exports.say(who, what, *args, **kwargs)
  File "C:\Users\ASUS\Downloads\renpy-8.0.3-sdk\renpy\exports.py", line 1373, in say
    who(what, *args, **kwargs)
  File "C:\Users\ASUS\Downloads\renpy-8.0.3-sdk\renpy\character.py", line 1251, in __call__
    who = self.prefix_suffix("who", self.who_prefix, who, self.who_suffix)
  File "C:\Users\ASUS\Downloads\renpy-8.0.3-sdk\renpy\character.py", line 1172, in prefix_suffix
    return (sub(prefix) + sub(body) + sub(suffix))
  File "C:\Users\ASUS\Downloads\renpy-8.0.3-sdk\renpy\character.py", line 1152, in sub
    return renpy.substitutions.substitute(s, scope=scope, force=force, translate=translate)[0]
  File "C:\Users\ASUS\Downloads\renpy-8.0.3-sdk\renpy\substitutions.py", line 278, in substitute
    s = formatter.vformat(s, (), kwargs) # type: ignore
  File "/home/tom/ab/renpy-build/tmp/install.linux-x86_64/lib/python3.9/string.py", line 165, in vformat
  File "/home/tom/ab/renpy-build/tmp/install.linux-x86_64/lib/python3.9/string.py", line 205, in _vformat
  File "C:\Users\ASUS\Downloads\renpy-8.0.3-sdk\renpy\substitutions.py", line 168, in get_field
    obj, arg_used = super(Formatter, self).get_field(field_name, args, kwargs)
  File "/home/tom/ab/renpy-build/tmp/install.linux-x86_64/lib/python3.9/string.py", line 270, in get_field
  File "/home/tom/ab/renpy-build/tmp/install.linux-x86_64/lib/python3.9/string.py", line 227, in get_value
KeyError: 'playername'

Windows-10-10.0.22000 AMD64
Ren'Py 8.0.3.22090809
GameProjects 1.0
Wed Dec  7 19:45:24 2022
